<?xml version="1.0"?>
<robot name="my_robot">

    <link name="chassis">
        <visual>
            <origin xyz="0 0 0.05" rpy="0 0 0"/>
            <geometry>
                <box size="0.3 0.2 0.1"/>
            </geometry>
        </visual>
        <collision>
            <origin xyz="0 0 0.05"/>
            <geometry>
                <box size="0.3 0.2 0.1"/>
            </geometry>
        </collision>
        <inertial>
            <origin xyz="0 0 0" rpy="0 0 0"/>
            <mass value="1.0"/>
            <inertia ixx="0.004166" ixy="0.0" ixz="0.0" iyy="0.008333" iyz="0.0" izz="0.0108333"/>
        </inertial>
    </link>

    <link name="left_wheel">
        <visual>
            <geometry>
                <cylinder radius="0.05" length="0.04"/>
            </geometry>
        </visual>
        <collision>
            <geometry>
                <cylinder radius="0.05" length="0.04"/>
            </geometry>
        </collision>
        <inertial>
            <origin xyz="0 0 0" rpy="0 0 0"/>
            <mass value="0.1"/>
            <inertia ixx="0.0000758333" ixy="0.0" ixz="0.0" iyy="0.0000758333" iyz="0.0" izz="0.0000208333"/>
        </inertial>
    </link>

    <link name="right_wheel">
        <visual>
            <geometry>
                <cylinder radius="0.05" length="0.04"/>
            </geometry>
        </visual>
        <collision>
            <geometry>
                <cylinder radius="0.05" length="0.04"/>
            </geometry>
        </collision>
        <inertial>
            <origin xyz="0 0 0" rpy="0 0 0"/>
            <mass value="0.1"/>
            <inertia ixx="0.0000758333" ixy="0.0" ixz="0.0" iyy="0.0000758333" iyz="0.0" izz="0.0000208333"/>
        </inertial>
    </link>

    <link name="sensor">
        <visual>
            <geometry>
                <box size="0.05 0.1 0.05"/>
            </geometry>
        </visual>
        <collision>
            <geometry>
                <box size="0.05 0.1 0.05"/>
            </geometry>
        </collision>
        <inertial>
            <origin xyz="0 0 0" rpy="0 0 0"/>
            <mass value="0.1"/>
            <inertia ixx="0.000010417" ixy="0.0" ixz="0.0" iyy="0.000041667" iyz="0.0" izz="0.000010417"/>
        </inertial>
    </link>

    <joint name="left_wheel_joint" type="continuous">
        <parent link="chassis"/>
        <child link="left_wheel"/>
        <origin xyz="0 0.15 0.05" rpy="1.5708 0 0"/>
    </joint>

    <joint name="sensor_connection" type="fixed">
        <parent link="chassis"/>
        <child link="sensor"/>
        <origin xyz="0.17 0 0.05" rpy="0 0 0"/>
    </joint>

    <joint name="right_wheel_joint" type="continuous">
        <parent link="chassis"/>
        <child link="right_wheel"/>
        <origin xyz="0 -0.15 0.05" rpy="1.5708 0 0"/>
    </joint>

    <gazebo reference="chassis">
        <material>Gazebo/Blue</material>
    </gazebo>

    <gazebo reference="left_wheel">
        <material>Gazebo/Black</material>
    </gazebo>

    <gazebo reference="right_wheel">
        <material>Gazebo/Black</material>
    </gazebo>

    <gazebo reference="sensor">
        <material>Gazebo/Red</material>
    </gazebo>

</robot>